<sdf version='1.7'>
  <world name='myworld'>
    <model name='greenhouse'>
      <frame name='greenhouse::__model__' attached_to='greenhouse::front_wall'>
        <pose relative_to='__model__'>0 0 0 0 -0 0</pose>
      </frame>
      <static>1</static>
      <link name='greenhouse::front_wall'>
        <pose relative_to='greenhouse::__model__'>0 -3 0 0 -0 0</pose>
        <collision name='front_wall_collision'>
          <geometry>
            <box>
              <size>6 0.2 2.5</size>
            </box>
          </geometry>
          <max_contacts>10</max_contacts>
          <surface>
            <contact>
              <ode/>
            </contact>
            <bounce/>
            <friction>
              <torsional>
                <ode/>
              </torsional>
              <ode/>
            </friction>
          </surface>
        </collision>
        <visual name='front_wall_visual'>
          <geometry>
            <box>
              <size>6 0.2 2.5</size>
            </box>
          </geometry>
          <material>
            <ambient>0 0.8 0 1</ambient>
            <diffuse>0 0.8 0 1</diffuse>
            <specular>0.1 0.1 0.1 1</specular>
          </material>
        </visual>
        <self_collide>0</self_collide>
        <enable_wind>0</enable_wind>
        <kinematic>0</kinematic>
      </link>
      <link name='greenhouse::back_wall'>
        <pose relative_to='greenhouse::__model__'>0 3 0 0 -0 0</pose>
        <collision name='back_wall_collision'>
          <geometry>
            <box>
              <size>6 0.2 2.5</size>
            </box>
          </geometry>
          <max_contacts>10</max_contacts>
          <surface>
            <contact>
              <ode/>
            </contact>
            <bounce/>
            <friction>
              <torsional>
                <ode/>
              </torsional>
              <ode/>
            </friction>
          </surface>
        </collision>
        <visual name='back_wall_visual'>
          <geometry>
            <box>
              <size>6 0.2 2.5</size>
            </box>
          </geometry>
          <material>
            <ambient>0 0.8 0 1</ambient>
            <diffuse>0 0.8 0 1</diffuse>
            <specular>0.1 0.1 0.1 1</specular>
          </material>
        </visual>
        <self_collide>0</self_collide>
        <enable_wind>0</enable_wind>
        <kinematic>0</kinematic>
      </link>
      <link name='greenhouse::left_wall'>
        <pose relative_to='greenhouse::__model__'>-3 0 0 0 -0 0</pose>
        <collision name='left_wall_collision'>
          <geometry>
            <box>
              <size>0.2 6 2.5</size>
            </box>
          </geometry>
          <max_contacts>10</max_contacts>
          <surface>
            <contact>
              <ode/>
            </contact>
            <bounce/>
            <friction>
              <torsional>
                <ode/>
              </torsional>
              <ode/>
            </friction>
          </surface>
        </collision>
        <visual name='left_wall_visual'>
          <geometry>
            <box>
              <size>0.2 6 2.5</size>
            </box>
          </geometry>
          <material>
            <ambient>0 0.8 0 1</ambient>
            <diffuse>0 0.8 0 1</diffuse>
            <specular>0.1 0.1 0.1 1</specular>
          </material>
        </visual>
        <self_collide>0</self_collide>
        <enable_wind>0</enable_wind>
        <kinematic>0</kinematic>
      </link>
      <link name='greenhouse::right_wall'>
        <pose relative_to='greenhouse::__model__'>3 0 0 0 -0 0</pose>
        <collision name='right_wall_collision'>
          <geometry>
            <box>
              <size>0.2 6 2.5</size>
            </box>
          </geometry>
          <max_contacts>10</max_contacts>
          <surface>
            <contact>
              <ode/>
            </contact>
            <bounce/>
            <friction>
              <torsional>
                <ode/>
              </torsional>
              <ode/>
            </friction>
          </surface>
        </collision>
        <visual name='right_wall_visual'>
          <geometry>
            <box>
              <size>0.2 6 2.5</size>
            </box>
          </geometry>
          <material>
            <ambient>0 0.8 0 1</ambient>
            <diffuse>0 0.8 0 1</diffuse>
            <specular>0.1 0.1 0.1 1</specular>
          </material>
        </visual>
        <self_collide>0</self_collide>
        <enable_wind>0</enable_wind>
        <kinematic>0</kinematic>
      </link>
      <link name='greenhouse::floor'>
        <pose relative_to='greenhouse::__model__'>0 0 0 0 -0 0</pose>
        <collision name='floor_collision'>
          <geometry>
            <box>
              <size>6 6 0.2</size>
            </box>
          </geometry>
          <max_contacts>10</max_contacts>
          <surface>
            <contact>
              <ode/>
            </contact>
            <bounce/>
            <friction>
              <torsional>
                <ode/>
              </torsional>
              <ode/>
            </friction>
          </surface>
        </collision>
        <visual name='floor_visual'>
          <geometry>
            <box>
              <size>6 6 0.2</size>
            </box>
          </geometry>
          <material>
            <ambient>0.5 0.5 0.5 1</ambient>
            <diffuse>0.5 0.5 0.5 1</diffuse>
            <specular>0.1 0.1 0.1 1</specular>
          </material>
        </visual>
        <self_collide>0</self_collide>
        <enable_wind>0</enable_wind>
        <kinematic>0</kinematic>
      </link>
      <link name='greenhouse::roof'>
        <pose relative_to='greenhouse::__model__'>0 0 2.5 0 -0 0</pose>
        <collision name='roof_collision'>
          <geometry>
            <box>
              <size>6 6 0.1</size>
            </box>
          </geometry>
          <max_contacts>10</max_contacts>
          <surface>
            <contact>
              <ode/>
            </contact>
            <bounce/>
            <friction>
              <torsional>
                <ode/>
              </torsional>
              <ode/>
            </friction>
          </surface>
        </collision>
        <visual name='roof_visual'>
          <geometry>
            <box>
              <size>6 6 0.1</size>
            </box>
          </geometry>
          <material>
            <ambient>0.7 0.9 1 1</ambient>
            <diffuse>0.7 0.9 1 1</diffuse>
            <specular>0.5 0.5 0.5 1</specular>
            <emissive>0.2 0.2 0.2 1</emissive>
          </material>
        </visual>
        <self_collide>0</self_collide>
        <enable_wind>0</enable_wind>
        <kinematic>0</kinematic>
      </link>
    </model>
    <model name='robot_1'>
      <frame name='robot::__model__' attached_to='robot::chassis'>
        <pose relative_to='__model__'>-1 -1 0 0 -0 0</pose>
      </frame>
      <link name='robot::chassis'>
        <pose relative_to='robot::__model__'>0 0 0.1 0 -0 0</pose>
        <inertial>
          <mass>10</mass>
          <inertia>
            <ixx>0.1</ixx>
            <ixy>0</ixy>
            <ixz>0</ixz>
            <iyy>0.1</iyy>
            <iyz>0</iyz>
            <izz>0.1</izz>
          </inertia>
          <pose>0 0 0 0 -0 0</pose>
        </inertial>
        <collision name='chassis_collision'>
          <geometry>
            <box>
              <size>0.3 0.2 0.1</size>
            </box>
          </geometry>
          <max_contacts>10</max_contacts>
          <surface>
            <contact>
              <ode/>
            </contact>
            <bounce/>
            <friction>
              <torsional>
                <ode/>
              </torsional>
              <ode/>
            </friction>
          </surface>
        </collision>
        <visual name='chassis_visual'>
          <geometry>
            <box>
              <size>0.3 0.2 0.1</size>
            </box>
          </geometry>
          <material>
            <ambient>0.3 0.3 0.3 1</ambient>
            <diffuse>0.5 0.5 0.5 1</diffuse>
            <specular>0.2 0.2 0.2 1</specular>
          </material>
        </visual>
        <self_collide>0</self_collide>
        <enable_wind>0</enable_wind>
        <kinematic>0</kinematic>
      </link>
      <link name='robot::caster_wheel'>
        <pose relative_to='robot::__model__'>0.1 0 0.05 0 -0 0</pose>
        <inertial>
          <mass>0.5</mass>
          <inertia>
            <ixx>0.01</ixx>
            <ixy>0</ixy>
            <ixz>0</ixz>
            <iyy>0.01</iyy>
            <iyz>0</iyz>
            <izz>0.01</izz>
          </inertia>
          <pose>0 0 0 0 -0 0</pose>
        </inertial>
        <collision name='caster_collision'>
          <geometry>
            <sphere>
              <radius>0.03</radius>
            </sphere>
          </geometry>
          <max_contacts>10</max_contacts>
          <surface>
            <contact>
              <ode/>
            </contact>
            <bounce/>
            <friction>
              <torsional>
                <ode/>
              </torsional>
              <ode/>
            </friction>
          </surface>
        </collision>
        <visual name='caster_visual'>
          <geometry>
            <sphere>
              <radius>0.03</radius>
            </sphere>
          </geometry>
          <material>
            <ambient>0.2 0.2 0.2 1</ambient>
            <diffuse>0.3 0.3 0.3 1</diffuse>
            <specular>0.1 0.1 0.1 1</specular>
          </material>
        </visual>
        <self_collide>0</self_collide>
        <enable_wind>0</enable_wind>
        <kinematic>0</kinematic>
      </link>
      <link name='robot::left_front_wheel'>
        <pose relative_to='robot::__model__'>0.08 0.1 0.05 3.14159 1.57079 3.14159</pose>
        <inertial>
          <mass>1</mass>
          <inertia>
            <ixx>0.01</ixx>
            <ixy>0</ixy>
            <ixz>0</ixz>
            <iyy>0.01</iyy>
            <iyz>0</iyz>
            <izz>0.01</izz>
          </inertia>
          <pose>0 0 0 0 -0 0</pose>
        </inertial>
        <collision name='left_front_wheel_collision'>
          <geometry>
            <cylinder>
              <radius>0.05</radius>
              <length>0.03</length>
            </cylinder>
          </geometry>
          <max_contacts>10</max_contacts>
          <surface>
            <contact>
              <ode/>
            </contact>
            <bounce/>
            <friction>
              <torsional>
                <ode/>
              </torsional>
              <ode/>
            </friction>
          </surface>
        </collision>
        <visual name='left_front_wheel_visual'>
          <geometry>
            <cylinder>
              <radius>0.05</radius>
              <length>0.03</length>
            </cylinder>
          </geometry>
          <material>
            <ambient>0 0 0 1</ambient>
            <diffuse>0.1 0.1 0.1 1</diffuse>
            <specular>0.05 0.05 0.05 1</specular>
          </material>
        </visual>
        <self_collide>0</self_collide>
        <enable_wind>0</enable_wind>
        <kinematic>0</kinematic>
      </link>
      <link name='robot::right_front_wheel'>
        <pose relative_to='robot::__model__'>0.08 -0.1 0.05 3.14159 1.57079 3.14159</pose>
        <inertial>
          <mass>1</mass>
          <inertia>
            <ixx>0.01</ixx>
            <ixy>0</ixy>
            <ixz>0</ixz>
            <iyy>0.01</iyy>
            <iyz>0</iyz>
            <izz>0.01</izz>
          </inertia>
          <pose>0 0 0 0 -0 0</pose>
        </inertial>
        <collision name='right_front_wheel_collision'>
          <geometry>
            <cylinder>
              <radius>0.05</radius>
              <length>0.03</length>
            </cylinder>
          </geometry>
          <max_contacts>10</max_contacts>
          <surface>
            <contact>
              <ode/>
            </contact>
            <bounce/>
            <friction>
              <torsional>
                <ode/>
              </torsional>
              <ode/>
            </friction>
          </surface>
        </collision>
        <visual name='right_front_wheel_visual'>
          <geometry>
            <cylinder>
              <radius>0.05</radius>
              <length>0.03</length>
            </cylinder>
          </geometry>
          <material>
            <ambient>0 0 0 1</ambient>
            <diffuse>0.1 0.1 0.1 1</diffuse>
            <specular>0.05 0.05 0.05 1</specular>
          </material>
        </visual>
        <self_collide>0</self_collide>
        <enable_wind>0</enable_wind>
        <kinematic>0</kinematic>
      </link>
      <link name='robot::left_rear_wheel'>
        <pose relative_to='robot::__model__'>-0.08 0.1 0.05 3.14159 1.57079 3.14159</pose>
        <inertial>
          <mass>1</mass>
          <inertia>
            <ixx>0.01</ixx>
            <ixy>0</ixy>
            <ixz>0</ixz>
            <iyy>0.01</iyy>
            <iyz>0</iyz>
            <izz>0.01</izz>
          </inertia>
          <pose>0 0 0 0 -0 0</pose>
        </inertial>
        <collision name='left_rear_wheel_collision'>
          <geometry>
            <cylinder>
              <radius>0.05</radius>
              <length>0.03</length>
            </cylinder>
          </geometry>
          <max_contacts>10</max_contacts>
          <surface>
            <contact>
              <ode/>
            </contact>
            <bounce/>
            <friction>
              <torsional>
                <ode/>
              </torsional>
              <ode/>
            </friction>
          </surface>
        </collision>
        <visual name='left_rear_wheel_visual'>
          <geometry>
            <cylinder>
              <radius>0.05</radius>
              <length>0.03</length>
            </cylinder>
          </geometry>
          <material>
            <ambient>0 0 0 1</ambient>
            <diffuse>0.1 0.1 0.1 1</diffuse>
            <specular>0.05 0.05 0.05 1</specular>
          </material>
        </visual>
        <self_collide>0</self_collide>
        <enable_wind>0</enable_wind>
        <kinematic>0</kinematic>
      </link>
      <link name='robot::right_rear_wheel'>
        <pose relative_to='robot::__model__'>-0.08 -0.1 0.05 3.14159 1.57079 3.14159</pose>
        <inertial>
          <mass>1</mass>
          <inertia>
            <ixx>0.01</ixx>
            <ixy>0</ixy>
            <ixz>0</ixz>
            <iyy>0.01</iyy>
            <iyz>0</iyz>
            <izz>0.01</izz>
          </inertia>
          <pose>0 0 0 0 -0 0</pose>
        </inertial>
        <collision name='right_rear_wheel_collision'>
          <geometry>
            <cylinder>
              <radius>0.05</radius>
              <length>0.03</length>
            </cylinder>
          </geometry>
          <max_contacts>10</max_contacts>
          <surface>
            <contact>
              <ode/>
            </contact>
            <bounce/>
            <friction>
              <torsional>
                <ode/>
              </torsional>
              <ode/>
            </friction>
          </surface>
        </collision>
        <visual name='right_rear_wheel_visual'>
          <geometry>
            <cylinder>
              <radius>0.05</radius>
              <length>0.03</length>
            </cylinder>
          </geometry>
          <material>
            <ambient>0 0 0 1</ambient>
            <diffuse>0.1 0.1 0.1 1</diffuse>
            <specular>0.05 0.05 0.05 1</specular>
          </material>
        </visual>
        <self_collide>0</self_collide>
        <enable_wind>0</enable_wind>
        <kinematic>0</kinematic>
      </link>
      <joint name='robot::caster_wheel_joint' type='ball'>
        <parent>robot::chassis</parent>
        <child>robot::caster_wheel</child>
      </joint>
      <joint name='robot::left_front_wheel_joint' type='revolute'>
        <parent>robot::chassis</parent>
        <child>robot::left_front_wheel</child>
        <axis>
          <xyz>0 1 0</xyz>
          <limit>
            <lower>-1e+16</lower>
            <upper>1e+16</upper>
          </limit>
          <dynamics>
            <spring_reference>0</spring_reference>
            <spring_stiffness>0</spring_stiffness>
          </dynamics>
        </axis>
      </joint>
      <joint name='robot::right_front_wheel_joint' type='revolute'>
        <parent>robot::chassis</parent>
        <child>robot::right_front_wheel</child>
        <axis>
          <xyz>0 1 0</xyz>
          <limit>
            <lower>-1e+16</lower>
            <upper>1e+16</upper>
          </limit>
          <dynamics>
            <spring_reference>0</spring_reference>
            <spring_stiffness>0</spring_stiffness>
          </dynamics>
        </axis>
      </joint>
      <joint name='robot::left_rear_wheel_joint' type='revolute'>
        <parent>robot::chassis</parent>
        <child>robot::left_rear_wheel</child>
        <axis>
          <xyz>0 1 0</xyz>
          <limit>
            <lower>-1e+16</lower>
            <upper>1e+16</upper>
          </limit>
          <dynamics>
            <spring_reference>0</spring_reference>
            <spring_stiffness>0</spring_stiffness>
          </dynamics>
        </axis>
      </joint>
      <joint name='robot::right_rear_wheel_joint' type='revolute'>
        <parent>robot::chassis</parent>
        <child>robot::right_rear_wheel</child>
        <axis>
          <xyz>0 1 0</xyz>
          <limit>
            <lower>-1e+16</lower>
            <upper>1e+16</upper>
          </limit>
          <dynamics>
            <spring_reference>0</spring_reference>
            <spring_stiffness>0</spring_stiffness>
          </dynamics>
        </axis>
      </joint>
    </model>
    <model name='robot_2'>
      <frame name='robot::__model__' attached_to='robot::chassis'>
        <pose relative_to='__model__'>1 1 0 0 -0 0</pose>
      </frame>
      <link name='robot::chassis'>
        <pose relative_to='robot::__model__'>0 0 0.1 0 -0 0</pose>
        <inertial>
          <mass>10</mass>
          <inertia>
            <ixx>0.1</ixx>
            <ixy>0</ixy>
            <ixz>0</ixz>
            <iyy>0.1</iyy>
            <iyz>0</iyz>
            <izz>0.1</izz>
          </inertia>
          <pose>0 0 0 0 -0 0</pose>
        </inertial>
        <collision name='chassis_collision'>
          <geometry>
            <box>
              <size>0.3 0.2 0.1</size>
            </box>
          </geometry>
          <max_contacts>10</max_contacts>
          <surface>
            <contact>
              <ode/>
            </contact>
            <bounce/>
            <friction>
              <torsional>
                <ode/>
              </torsional>
              <ode/>
            </friction>
          </surface>
        </collision>
        <visual name='chassis_visual'>
          <geometry>
            <box>
              <size>0.3 0.2 0.1</size>
            </box>
          </geometry>
          <material>
            <ambient>0.3 0.3 0.3 1</ambient>
            <diffuse>0.5 0.5 0.5 1</diffuse>
            <specular>0.2 0.2 0.2 1</specular>
          </material>
        </visual>
        <self_collide>0</self_collide>
        <enable_wind>0</enable_wind>
        <kinematic>0</kinematic>
      </link>
      <link name='robot::caster_wheel'>
        <pose relative_to='robot::__model__'>0.1 0 0.05 0 -0 0</pose>
        <inertial>
          <mass>0.5</mass>
          <inertia>
            <ixx>0.01</ixx>
            <ixy>0</ixy>
            <ixz>0</ixz>
            <iyy>0.01</iyy>
            <iyz>0</iyz>
            <izz>0.01</izz>
          </inertia>
          <pose>0 0 0 0 -0 0</pose>
        </inertial>
        <collision name='caster_collision'>
          <geometry>
            <sphere>
              <radius>0.03</radius>
            </sphere>
          </geometry>
          <max_contacts>10</max_contacts>
          <surface>
            <contact>
              <ode/>
            </contact>
            <bounce/>
            <friction>
              <torsional>
                <ode/>
              </torsional>
              <ode/>
            </friction>
          </surface>
        </collision>
        <visual name='caster_visual'>
          <geometry>
            <sphere>
              <radius>0.03</radius>
            </sphere>
          </geometry>
          <material>
            <ambient>0.2 0.2 0.2 1</ambient>
            <diffuse>0.3 0.3 0.3 1</diffuse>
            <specular>0.1 0.1 0.1 1</specular>
          </material>
        </visual>
        <self_collide>0</self_collide>
        <enable_wind>0</enable_wind>
        <kinematic>0</kinematic>
      </link>
      <link name='robot::left_front_wheel'>
        <pose relative_to='robot::__model__'>0.08 0.1 0.05 3.14159 1.57079 3.14159</pose>
        <inertial>
          <mass>1</mass>
          <inertia>
            <ixx>0.01</ixx>
            <ixy>0</ixy>
            <ixz>0</ixz>
            <iyy>0.01</iyy>
            <iyz>0</iyz>
            <izz>0.01</izz>
          </inertia>
          <pose>0 0 0 0 -0 0</pose>
        </inertial>
        <collision name='left_front_wheel_collision'>
          <geometry>
            <cylinder>
              <radius>0.05</radius>
              <length>0.03</length>
            </cylinder>
          </geometry>
          <max_contacts>10</max_contacts>
          <surface>
            <contact>
              <ode/>
            </contact>
            <bounce/>
            <friction>
              <torsional>
                <ode/>
              </torsional>
              <ode/>
            </friction>
          </surface>
        </collision>
        <visual name='left_front_wheel_visual'>
          <geometry>
            <cylinder>
              <radius>0.05</radius>
              <length>0.03</length>
            </cylinder>
          </geometry>
          <material>
            <ambient>0 0 0 1</ambient>
            <diffuse>0.1 0.1 0.1 1</diffuse>
            <specular>0.05 0.05 0.05 1</specular>
          </material>
        </visual>
        <self_collide>0</self_collide>
        <enable_wind>0</enable_wind>
        <kinematic>0</kinematic>
      </link>
      <link name='robot::right_front_wheel'>
        <pose relative_to='robot::__model__'>0.08 -0.1 0.05 3.14159 1.57079 3.14159</pose>
        <inertial>
          <mass>1</mass>
          <inertia>
            <ixx>0.01</ixx>
            <ixy>0</ixy>
            <ixz>0</ixz>
            <iyy>0.01</iyy>
            <iyz>0</iyz>
            <izz>0.01</izz>
          </inertia>
          <pose>0 0 0 0 -0 0</pose>
        </inertial>
        <collision name='right_front_wheel_collision'>
          <geometry>
            <cylinder>
              <radius>0.05</radius>
              <length>0.03</length>
            </cylinder>
          </geometry>
          <max_contacts>10</max_contacts>
          <surface>
            <contact>
              <ode/>
            </contact>
            <bounce/>
            <friction>
              <torsional>
                <ode/>
              </torsional>
              <ode/>
            </friction>
          </surface>
        </collision>
        <visual name='right_front_wheel_visual'>
          <geometry>
            <cylinder>
              <radius>0.05</radius>
              <length>0.03</length>
            </cylinder>
          </geometry>
          <material>
            <ambient>0 0 0 1</ambient>
            <diffuse>0.1 0.1 0.1 1</diffuse>
            <specular>0.05 0.05 0.05 1</specular>
          </material>
        </visual>
        <self_collide>0</self_collide>
        <enable_wind>0</enable_wind>
        <kinematic>0</kinematic>
      </link>
      <link name='robot::left_rear_wheel'>
        <pose relative_to='robot::__model__'>-0.08 0.1 0.05 3.14159 1.57079 3.14159</pose>
        <inertial>
          <mass>1</mass>
          <inertia>
            <ixx>0.01</ixx>
            <ixy>0</ixy>
            <ixz>0</ixz>
            <iyy>0.01</iyy>
            <iyz>0</iyz>
            <izz>0.01</izz>
          </inertia>
          <pose>0 0 0 0 -0 0</pose>
        </inertial>
        <collision name='left_rear_wheel_collision'>
          <geometry>
            <cylinder>
              <radius>0.05</radius>
              <length>0.03</length>
            </cylinder>
          </geometry>
          <max_contacts>10</max_contacts>
          <surface>
            <contact>
              <ode/>
            </contact>
            <bounce/>
            <friction>
              <torsional>
                <ode/>
              </torsional>
              <ode/>
            </friction>
          </surface>
        </collision>
        <visual name='left_rear_wheel_visual'>
          <geometry>
            <cylinder>
              <radius>0.05</radius>
              <length>0.03</length>
            </cylinder>
          </geometry>
          <material>
            <ambient>0 0 0 1</ambient>
            <diffuse>0.1 0.1 0.1 1</diffuse>
            <specular>0.05 0.05 0.05 1</specular>
          </material>
        </visual>
        <self_collide>0</self_collide>
        <enable_wind>0</enable_wind>
        <kinematic>0</kinematic>
      </link>
      <link name='robot::right_rear_wheel'>
        <pose relative_to='robot::__model__'>-0.08 -0.1 0.05 3.14159 1.57079 3.14159</pose>
        <inertial>
          <mass>1</mass>
          <inertia>
            <ixx>0.01</ixx>
            <ixy>0</ixy>
            <ixz>0</ixz>
            <iyy>0.01</iyy>
            <iyz>0</iyz>
            <izz>0.01</izz>
          </inertia>
          <pose>0 0 0 0 -0 0</pose>
        </inertial>
        <collision name='right_rear_wheel_collision'>
          <geometry>
            <cylinder>
              <radius>0.05</radius>
              <length>0.03</length>
            </cylinder>
          </geometry>
          <max_contacts>10</max_contacts>
          <surface>
            <contact>
              <ode/>
            </contact>
            <bounce/>
            <friction>
              <torsional>
                <ode/>
              </torsional>
              <ode/>
            </friction>
          </surface>
        </collision>
        <visual name='right_rear_wheel_visual'>
          <geometry>
            <cylinder>
              <radius>0.05</radius>
              <length>0.03</length>
            </cylinder>
          </geometry>
          <material>
            <ambient>0 0 0 1</ambient>
            <diffuse>0.1 0.1 0.1 1</diffuse>
            <specular>0.05 0.05 0.05 1</specular>
          </material>
        </visual>
        <self_collide>0</self_collide>
        <enable_wind>0</enable_wind>
        <kinematic>0</kinematic>
      </link>
      <joint name='robot::caster_wheel_joint' type='ball'>
        <parent>robot::chassis</parent>
        <child>robot::caster_wheel</child>
      </joint>
      <joint name='robot::left_front_wheel_joint' type='revolute'>
        <parent>robot::chassis</parent>
        <child>robot::left_front_wheel</child>
        <axis>
          <xyz>0 1 0</xyz>
          <limit>
            <lower>-1e+16</lower>
            <upper>1e+16</upper>
          </limit>
          <dynamics>
            <spring_reference>0</spring_reference>
            <spring_stiffness>0</spring_stiffness>
          </dynamics>
        </axis>
      </joint>
      <joint name='robot::right_front_wheel_joint' type='revolute'>
        <parent>robot::chassis</parent>
        <child>robot::right_front_wheel</child>
        <axis>
          <xyz>0 1 0</xyz>
          <limit>
            <lower>-1e+16</lower>
            <upper>1e+16</upper>
          </limit>
          <dynamics>
            <spring_reference>0</spring_reference>
            <spring_stiffness>0</spring_stiffness>
          </dynamics>
        </axis>
      </joint>
      <joint name='robot::left_rear_wheel_joint' type='revolute'>
        <parent>robot::chassis</parent>
        <child>robot::left_rear_wheel</child>
        <axis>
          <xyz>0 1 0</xyz>
          <limit>
            <lower>-1e+16</lower>
            <upper>1e+16</upper>
          </limit>
          <dynamics>
            <spring_reference>0</spring_reference>
            <spring_stiffness>0</spring_stiffness>
          </dynamics>
        </axis>
      </joint>
      <joint name='robot::right_rear_wheel_joint' type='revolute'>
        <parent>robot::chassis</parent>
        <child>robot::right_rear_wheel</child>
        <axis>
          <xyz>0 1 0</xyz>
          <limit>
            <lower>-1e+16</lower>
            <upper>1e+16</upper>
          </limit>
          <dynamics>
            <spring_reference>0</spring_reference>
            <spring_stiffness>0</spring_stiffness>
          </dynamics>
        </axis>
      </joint>
    </model>
    <plugin name='hello_world_plugin' filename='libhello.so'/>
    <gravity>0 0 -9.8</gravity>
    <magnetic_field>6e-06 2.3e-05 -4.2e-05</magnetic_field>
    <atmosphere type='adiabatic'/>
    <physics type='ode'>
      <max_step_size>0.001</max_step_size>
      <real_time_factor>1</real_time_factor>
      <real_time_update_rate>1000</real_time_update_rate>
    </physics>
    <scene>
      <ambient>0.4 0.4 0.4 1</ambient>
      <background>0.7 0.7 0.7 1</background>
      <shadows>1</shadows>
    </scene>
    <wind/>
    <spherical_coordinates>
      <surface_model>EARTH_WGS84</surface_model>
      <latitude_deg>0</latitude_deg>
      <longitude_deg>0</longitude_deg>
      <elevation>0</elevation>
      <heading_deg>0</heading_deg>
    </spherical_coordinates>
    <light name='user_directional_light_0' type='directional'>
      <pose>5.98576 1.89907 1 0 -0 0</pose>
      <diffuse>0.5 0.5 0.5 1</diffuse>
      <specular>0.1 0.1 0.1 1</specular>
      <direction>0.1 0.1 -0.9</direction>
      <attenuation>
        <range>20</range>
        <constant>0.5</constant>
        <linear>0.01</linear>
        <quadratic>0.001</quadratic>
      </attenuation>
      <cast_shadows>1</cast_shadows>
    </light>
    <light name='user_directional_light_1' type='directional'>
      <pose>0.092436 1.84075 1 0 -0 0</pose>
      <diffuse>0.5 0.5 0.5 1</diffuse>
      <specular>0.1 0.1 0.1 1</specular>
      <direction>0.1 0.1 -0.9</direction>
      <attenuation>
        <range>20</range>
        <constant>0.5</constant>
        <linear>0.01</linear>
        <quadratic>0.001</quadratic>
      </attenuation>
      <cast_shadows>1</cast_shadows>
    </light>
    <light name='user_point_light_0' type='point'>
      <pose>0.500876 0.028798 1 0 -0 0</pose>
      <diffuse>0.5 0.5 0.5 1</diffuse>
      <specular>0.1 0.1 0.1 1</specular>
      <attenuation>
        <range>20</range>
        <constant>0.5</constant>
        <linear>0.01</linear>
        <quadratic>0.001</quadratic>
      </attenuation>
      <cast_shadows>0</cast_shadows>
      <direction>0 0 -1</direction>
    </light>
    <model name='robo-import'>
      <model name='husky'>
        <pose>0 0 0 0 -0 0</pose>
        <link name='base_link'>
          <collision name='collision'>
            <pose>0 0 0.1 0 -0 0</pose>
            <geometry>
              <box>
                <size>1.0074 0.5709 0.2675</size>
              </box>
            </geometry>
            <max_contacts>10</max_contacts>
            <surface>
              <contact>
                <ode/>
              </contact>
              <bounce/>
              <friction>
                <torsional>
                  <ode/>
                </torsional>
                <ode/>
              </friction>
            </surface>
          </collision>
          <inertial>
            <mass>33.855</mass>
            <pose>-0.085613 -0.00084 0.238145 0 -0 0</pose>
            <inertia>
              <ixx>2.2343</ixx>
              <ixy>-0.023642</ixy>
              <ixz>0.275174</ixz>
              <iyy>3.42518</iyy>
              <iyz>0.00239624</iyz>
              <izz>2.1241</izz>
            </inertia>
          </inertial>
          <visual name='base'>
            <pose>0 0 0 0 -0 0</pose>
            <geometry>
              <mesh>
                <uri>model://husky/meshes/base_link.stl</uri>
              </mesh>
            </geometry>
            <material>
              <script>
                <name>Gazebo/FlatBlack</name>
                <uri>__default__</uri>
              </script>
            </material>
          </visual>
          <visual name='top_plate'>
            <pose>0 0 0 0 -0 0</pose>
            <geometry>
              <mesh>
                <uri>model://husky/meshes/top_plate.stl</uri>
              </mesh>
            </geometry>
            <material>
              <script>
                <name>Gazebo/Yellow</name>
                <uri>__default__</uri>
              </script>
            </material>
          </visual>
          <visual name='front_bumper'>
            <pose>0.47 0 0.091 0 -0 0</pose>
            <geometry>
              <mesh>
                <uri>model://husky/meshes/bumper.stl</uri>
              </mesh>
            </geometry>
            <material>
              <script>
                <name>Gazebo/FlatBlack</name>
                <uri>__default__</uri>
              </script>
            </material>
          </visual>
          <visual name='rear_bumper'>
            <pose>-0.47 0 0.091 0 -0 3.141</pose>
            <geometry>
              <mesh>
                <uri>model://husky/meshes/bumper.stl</uri>
              </mesh>
            </geometry>
            <material>
              <script>
                <name>Gazebo/FlatBlack</name>
                <uri>__default__</uri>
              </script>
            </material>
          </visual>
          <visual name='user_rail'>
            <pose>0.272 0 0.245 0 -0 0</pose>
            <geometry>
              <mesh>
                <uri>model://husky/meshes/user_rail.stl</uri>
              </mesh>
            </geometry>
            <material>
              <script>
                <name>Gazebo/Grey</name>
                <uri>__default__</uri>
              </script>
            </material>
          </visual>
          <self_collide>0</self_collide>
          <enable_wind>0</enable_wind>
          <kinematic>0</kinematic>
        </link>
        <link name='back_left_wheel'>
          <pose>-0.256 0.285475 0.035 0 -0 0</pose>
          <inertial>
            <mass>2.6357</mass>
            <pose>0 0 0 0 -0 0</pose>
            <inertia>
              <ixx>0.0246688</ixx>
              <ixy>0</ixy>
              <ixz>0</ixz>
              <iyy>0.0246688</iyy>
              <iyz>0</iyz>
              <izz>0.0441058</izz>
            </inertia>
          </inertial>
          <collision name='back_left_wheel_collision'>
            <pose>0 0 0 -1.5707 0 0</pose>
            <geometry>
              <cylinder>
                <radius>0.17775</radius>
                <length>0.1143</length>
              </cylinder>
            </geometry>
            <surface>
              <friction>
                <ode>
                  <mu>100000</mu>
                  <mu2>100000</mu2>
                  <slip1>0</slip1>
                  <slip2>0</slip2>
                </ode>
                <torsional>
                  <ode/>
                </torsional>
              </friction>
              <contact>
                <ode/>
              </contact>
              <bounce/>
            </surface>
            <max_contacts>10</max_contacts>
          </collision>
          <visual name='back_left_wheel'>
            <pose>0 0 0 -3.14159 0 0</pose>
            <geometry>
              <mesh>
                <uri>model://husky/meshes/wheel.stl</uri>
              </mesh>
            </geometry>
            <material>
              <script>
                <name>Gazebo/Grey</name>
                <uri>__default__</uri>
              </script>
            </material>
          </visual>
          <self_collide>0</self_collide>
          <enable_wind>0</enable_wind>
          <kinematic>0</kinematic>
        </link>
        <joint name='back_left_joint' type='revolute'>
          <parent>base_link</parent>
          <child>back_left_wheel</child>
          <axis>
            <xyz expressed_in='__model__'>0 1 0</xyz>
            <limit>
              <lower>-1e+16</lower>
              <upper>1e+16</upper>
            </limit>
            <dynamics>
              <spring_reference>0</spring_reference>
              <spring_stiffness>0</spring_stiffness>
            </dynamics>
          </axis>
          <physics>
            <ode>
              <limit>
                <cfm>0</cfm>
                <erp>0.9</erp>
              </limit>
            </ode>
          </physics>
        </joint>
        <link name='back_right_wheel'>
          <pose>-0.256 -0.285475 0.035 0 -0 0</pose>
          <inertial>
            <mass>2.6357</mass>
            <pose>0 0 0 0 -0 0</pose>
            <inertia>
              <ixx>0.0246688</ixx>
              <ixy>0</ixy>
              <ixz>0</ixz>
              <iyy>0.0246688</iyy>
              <iyz>0</iyz>
              <izz>0.0441058</izz>
            </inertia>
          </inertial>
          <collision name='back_right_wheel_collision'>
            <pose>0 0 0 -1.5707 0 0</pose>
            <geometry>
              <cylinder>
                <radius>0.17775</radius>
                <length>0.1143</length>
              </cylinder>
            </geometry>
            <surface>
              <friction>
                <ode>
                  <mu>100000</mu>
                  <mu2>100000</mu2>
                  <slip1>0</slip1>
                  <slip2>0</slip2>
                </ode>
                <torsional>
                  <ode/>
                </torsional>
              </friction>
              <contact>
                <ode/>
              </contact>
              <bounce/>
            </surface>
            <max_contacts>10</max_contacts>
          </collision>
          <visual name='back_right_wheel'>
            <pose>0 0 0 -3.14159 0 0</pose>
            <geometry>
              <mesh>
                <uri>model://husky/meshes/wheel.stl</uri>
              </mesh>
            </geometry>
            <material>
              <script>
                <name>Gazebo/Grey</name>
                <uri>__default__</uri>
              </script>
            </material>
          </visual>
          <self_collide>0</self_collide>
          <enable_wind>0</enable_wind>
          <kinematic>0</kinematic>
        </link>
        <joint name='back_right_joint' type='revolute'>
          <parent>base_link</parent>
          <child>back_right_wheel</child>
          <axis>
            <xyz expressed_in='__model__'>0 1 0</xyz>
            <limit>
              <lower>-1e+16</lower>
              <upper>1e+16</upper>
            </limit>
            <dynamics>
              <spring_reference>0</spring_reference>
              <spring_stiffness>0</spring_stiffness>
            </dynamics>
          </axis>
          <physics>
            <ode>
              <limit>
                <cfm>0</cfm>
                <erp>0.9</erp>
              </limit>
            </ode>
          </physics>
        </joint>
        <link name='front_left_wheel'>
          <pose>0.256 0.285475 0.035 0 -0 0</pose>
          <inertial>
            <mass>2.6357</mass>
            <pose>0 0 0 0 -0 0</pose>
            <inertia>
              <ixx>0.0246688</ixx>
              <ixy>0</ixy>
              <ixz>0</ixz>
              <iyy>0.0246688</iyy>
              <iyz>0</iyz>
              <izz>0.0441058</izz>
            </inertia>
          </inertial>
          <collision name='front_left_wheel_collision'>
            <pose>0 0 0 -1.5707 0 0</pose>
            <geometry>
              <cylinder>
                <radius>0.17775</radius>
                <length>0.1143</length>
              </cylinder>
            </geometry>
            <surface>
              <friction>
                <ode>
                  <mu>100000</mu>
                  <mu2>100000</mu2>
                  <slip1>0</slip1>
                  <slip2>0</slip2>
                </ode>
                <torsional>
                  <ode/>
                </torsional>
              </friction>
              <contact>
                <ode/>
              </contact>
              <bounce/>
            </surface>
            <max_contacts>10</max_contacts>
          </collision>
          <visual name='front_left_wheel'>
            <pose>0 0 0 -3.14159 0 0</pose>
            <geometry>
              <mesh>
                <uri>model://husky/meshes/wheel.stl</uri>
              </mesh>
            </geometry>
            <material>
              <script>
                <name>Gazebo/Grey</name>
                <uri>__default__</uri>
              </script>
            </material>
          </visual>
          <self_collide>0</self_collide>
          <enable_wind>0</enable_wind>
          <kinematic>0</kinematic>
        </link>
        <joint name='front_left_joint' type='revolute'>
          <parent>base_link</parent>
          <child>front_left_wheel</child>
          <axis>
            <xyz expressed_in='__model__'>0 1 0</xyz>
            <limit>
              <lower>-1e+16</lower>
              <upper>1e+16</upper>
            </limit>
            <dynamics>
              <spring_reference>0</spring_reference>
              <spring_stiffness>0</spring_stiffness>
            </dynamics>
          </axis>
          <physics>
            <ode>
              <limit>
                <cfm>0</cfm>
                <erp>0.9</erp>
              </limit>
            </ode>
          </physics>
        </joint>
        <link name='front_right_wheel'>
          <pose>0.256 -0.285475 0.035 0 -0 0</pose>
          <inertial>
            <mass>2.6357</mass>
            <pose>0 0 0 0 -0 0</pose>
            <inertia>
              <ixx>0.0246688</ixx>
              <ixy>0</ixy>
              <ixz>0</ixz>
              <iyy>0.0246688</iyy>
              <iyz>0</iyz>
              <izz>0.0441058</izz>
            </inertia>
          </inertial>
          <collision name='front_right_wheel_collision'>
            <pose>0 0 0 -1.5707 0 0</pose>
            <geometry>
              <cylinder>
                <radius>0.17775</radius>
                <length>0.1143</length>
              </cylinder>
            </geometry>
            <surface>
              <friction>
                <ode>
                  <mu>100000</mu>
                  <mu2>100000</mu2>
                  <slip1>0</slip1>
                  <slip2>0</slip2>
                </ode>
                <torsional>
                  <ode/>
                </torsional>
              </friction>
              <contact>
                <ode/>
              </contact>
              <bounce/>
            </surface>
            <max_contacts>10</max_contacts>
          </collision>
          <visual name='front_right_wheel'>
            <pose>0 0 0 -3.14159 0 0</pose>
            <geometry>
              <mesh>
                <uri>model://husky/meshes/wheel.stl</uri>
              </mesh>
            </geometry>
            <material>
              <script>
                <name>Gazebo/Grey</name>
                <uri>__default__</uri>
              </script>
            </material>
          </visual>
          <self_collide>0</self_collide>
          <enable_wind>0</enable_wind>
          <kinematic>0</kinematic>
        </link>
        <joint name='front_right_joint' type='revolute'>
          <parent>base_link</parent>
          <child>front_right_wheel</child>
          <axis>
            <xyz expressed_in='__model__'>0 1 0</xyz>
            <limit>
              <lower>-1e+16</lower>
              <upper>1e+16</upper>
            </limit>
            <dynamics>
              <spring_reference>0</spring_reference>
              <spring_stiffness>0</spring_stiffness>
            </dynamics>
          </axis>
          <physics>
            <ode>
              <limit>
                <cfm>0</cfm>
                <erp>0.9</erp>
              </limit>
            </ode>
          </physics>
        </joint>
        <plugin name='husky_diff_controller' filename='libhusky_gazebo_plugins.so'>
          <alwaysOn>1</alwaysOn>
          <updateRate>100.0</updateRate>
          <backLeftJoint>back_left_joint</backLeftJoint>
          <backRightJoint>back_right_joint</backRightJoint>
          <frontLeftJoint>front_left_joint</frontLeftJoint>
          <frontRightJoint>front_right_joint</frontRightJoint>
          <wheelSeparation>0.5709</wheelSeparation>
          <wheelDiameter>0.3555</wheelDiameter>
          <torque>35</torque>
        </plugin>
      </model>
      <static>0</static>
      <allow_auto_disable>1</allow_auto_disable>
      <pose>0.185942 0.006733 0.5 0 -0 0</pose>
    </model>
    <state world_name='myworld'>
      <sim_time>168 905000000</sim_time>
      <real_time>0 0</real_time>
      <wall_time>1773171888 916740820</wall_time>
      <iterations>168905</iterations>
      <model name='greenhouse'>
        <pose>0 0 0 0 -0 0</pose>
        <scale>1 1 1</scale>
        <link name='greenhouse::back_wall'>
          <pose>0 3 0 0 -0 0</pose>
          <velocity>0 0 0 0 -0 0</velocity>
          <acceleration>0 0 0 0 -0 0</acceleration>
          <wrench>0 0 0 0 -0 0</wrench>
        </link>
        <link name='greenhouse::floor'>
          <pose>0 0 0 0 -0 0</pose>
          <velocity>0 0 0 0 -0 0</velocity>
          <acceleration>0 0 0 0 -0 0</acceleration>
          <wrench>0 0 0 0 -0 0</wrench>
        </link>
        <link name='greenhouse::front_wall'>
          <pose>0 -3 0 0 -0 0</pose>
          <velocity>0 0 0 0 -0 0</velocity>
          <acceleration>0 0 0 0 -0 0</acceleration>
          <wrench>0 0 0 0 -0 0</wrench>
        </link>
        <link name='greenhouse::left_wall'>
          <pose>-3 0 0 0 -0 0</pose>
          <velocity>0 0 0 0 -0 0</velocity>
          <acceleration>0 0 0 0 -0 0</acceleration>
          <wrench>0 0 0 0 -0 0</wrench>
        </link>
        <link name='greenhouse::right_wall'>
          <pose>3 0 0 0 -0 0</pose>
          <velocity>0 0 0 0 -0 0</velocity>
          <acceleration>0 0 0 0 -0 0</acceleration>
          <wrench>0 0 0 0 -0 0</wrench>
        </link>
        <link name='greenhouse::roof'>
          <pose>0 0 2.5 0 -0 0</pose>
          <velocity>0 0 0 0 -0 0</velocity>
          <acceleration>0 0 0 0 -0 0</acceleration>
          <wrench>0 0 0 0 -0 0</wrench>
        </link>
      </model>
      <model name='robo-import'>
        <pose>0.185942 0.006733 0.5 0 -0 0</pose>
        <scale>1 1 1</scale>
        <model name='husky'>
          <pose>0.185942 0.006733 0.5 0 -0 0</pose>
          <scale>1 1 1</scale>
          <link name='back_left_wheel'>
            <pose>-0.070058 0.292208 0.535 0 -0 0</pose>
            <velocity>0 0 0 0 -0 0</velocity>
            <acceleration>0 0 0 0 -0 0</acceleration>
            <wrench>0 0 0 0 -0 0</wrench>
          </link>
          <link name='back_right_wheel'>
            <pose>-0.070058 -0.278742 0.535 0 -0 0</pose>
            <velocity>0 0 0 0 -0 0</velocity>
            <acceleration>0 0 0 0 -0 0</acceleration>
            <wrench>0 0 0 0 -0 0</wrench>
          </link>
          <link name='base_link'>
            <pose>0.185942 0.006733 0.5 0 -0 0</pose>
            <velocity>0 0 0 0 -0 0</velocity>
            <acceleration>0 0 0 0 -0 0</acceleration>
            <wrench>0 0 0 0 -0 0</wrench>
          </link>
          <link name='front_left_wheel'>
            <pose>0.441942 0.292208 0.535 0 -0 0</pose>
            <velocity>0 0 0 0 -0 0</velocity>
            <acceleration>0 0 0 0 -0 0</acceleration>
            <wrench>0 0 0 0 -0 0</wrench>
          </link>
          <link name='front_right_wheel'>
            <pose>0.441942 -0.278742 0.535 0 -0 0</pose>
            <velocity>0 0 0 0 -0 0</velocity>
            <acceleration>0 0 0 0 -0 0</acceleration>
            <wrench>0 0 0 0 -0 0</wrench>
          </link>
        </model>
      </model>
      <model name='robot_1'>
        <pose>0.931205 -0.121336 0.099998 -2e-06 -0 -0.18754</pose>
        <scale>1 1 1</scale>
        <link name='robot::caster_wheel'>
          <pose>-0.139457 -0.936004 0.15 -1e-05 1.9e-05 1.4e-05</pose>
          <velocity>-0.000224 -0.000431 -0.000922 0 -0 0</velocity>
          <acceleration>-0.230262 -0.913841 -1.84457 0 -0 0</acceleration>
          <wrench>-0.115131 -0.45692 -0.922287 0 -0 0</wrench>
        </link>
        <link name='robot::chassis'>
          <pose>-0.237703 -0.91736 0.2 -2e-06 -0 -0.18754</pose>
          <velocity>-0.001125 -0.000702 -0.002599 0.009522 -0.018858 -0.002067</velocity>
          <acceleration>-2.07714 -1.68662 -5.19739 0.195203 -0.015923 -1.79165</acceleration>
          <wrench>-20.7714 -16.8662 -51.9739 0 -0 0</wrench>
        </link>
        <link name='robot::left_front_wheel'>
          <pose>-0.140464 -0.834031 0.15 -2.45884 1.57077 -2.64638</pose>
          <velocity>-0.000194 -0.000526 7.4e-05 0.011643 -0.004321 -0.002923</velocity>
          <acceleration>-0.409587 -1.10581 0.147968 1.29355 -0.782224 -0.357319</acceleration>
          <wrench>-0.409587 -1.10581 0.147968 0 -0 0</wrench>
        </link>
        <link name='robot::left_rear_wheel'>
          <pose>-0.297656 -0.804198 0.15 3.0871 1.57078 2.89956</pose>
          <velocity>-2.3e-05 -0.000184 -0.002684 0.012125 -0.002301 -0.001998</velocity>
          <acceleration>-0.138673 -0.791548 -5.36848 2.25986 1.46081 1.48734</acceleration>
          <wrench>-0.138673 -0.791548 -5.36848 0 -0 0</wrench>
        </link>
        <link name='robot::right_front_wheel'>
          <pose>-0.17775 -1.03052 0.15 3.00497 1.57079 2.81743</pose>
          <velocity>-0.000552 -0.000455 -0.002543 0.011935 -0.002265 -0.002082</velocity>
          <acceleration>-0.665107 -1.05295 -5.08651 1.88002 1.38871 1.32002</acceleration>
          <wrench>-0.665107 -1.05295 -5.08651 0 -0 0</wrench>
        </link>
        <link name='robot::right_rear_wheel'>
          <pose>-0.334944 -1.00069 0.15 3.08738 1.57079 2.89984</pose>
          <velocity>-0.000484 -9.7e-05 -0.005207 0.012136 -0.002303 -0.002056</velocity>
          <acceleration>-0.599054 -0.70493 -10.4137 2.28116 1.46485 1.37172</acceleration>
          <wrench>-0.599054 -0.70493 -10.4137 0 -0 0</wrench>
        </link>
      </model>
      <model name='robot_2'>
        <pose>-1.32253 0.26258 0.100002 -2e-06 -0 -0.178467</pose>
        <scale>1 1 1</scale>
        <link name='robot::caster_wheel'>
          <pose>-0.062479 1.05142 0.15 -1e-05 1.9e-05 1.4e-05</pose>
          <velocity>-0.00022 -0.000433 -0.000922 0 -0 0</velocity>
          <acceleration>-0.222223 -0.916141 -1.84442 0 -0 0</acceleration>
          <wrench>-0.111111 -0.45807 -0.92221 0 -0 0</wrench>
        </link>
        <link name='robot::chassis'>
          <pose>-0.160891 1.06918 0.2 -2e-06 -0 -0.178467</pose>
          <velocity>-0.001119 -0.000712 -0.002599 0.009694 -0.018771 -0.002071</velocity>
          <acceleration>-2.06196 -1.70527 -5.19726 0.537975 0.158003 -1.7958</acceleration>
          <wrench>-20.6196 -17.0527 -51.9726 0 -0 0</wrench>
        </link>
        <link name='robot::left_front_wheel'>
          <pose>-0.064412 1.15338 0.15 -2.45886 1.57077 -2.63733</pose>
          <velocity>-0.00019 -0.000527 7.4e-05 0.011679 -0.004237 -0.002924</velocity>
          <acceleration>-0.401602 -1.10922 0.148666 1.3657 -0.951411 -0.356038</acceleration>
          <wrench>-0.401602 -1.10922 0.148666 0 -0 0</wrench>
        </link>
        <link name='robot::left_rear_wheel'>
          <pose>-0.221868 1.18179 0.15 3.08709 1.57078 2.90862</pose>
          <velocity>-2.2e-05 -0.000184 -0.002684 0.012147 -0.002191 -0.002002</velocity>
          <acceleration>-0.131342 -0.792291 -5.36829 2.30215 1.24087 1.48352</acceleration>
          <wrench>-0.131342 -0.792291 -5.36829 0 -0 0</wrench>
        </link>
        <link name='robot::right_front_wheel'>
          <pose>-0.099913 0.956564 0.15 3.00493 1.57079 2.82646</pose>
          <velocity>-0.000548 -0.00046 -0.002543 0.011957 -0.002157 -0.002086</velocity>
          <acceleration>-0.656194 -1.05892 -5.0867 1.92204 1.17229 1.31626</acceleration>
          <wrench>-0.656194 -1.05892 -5.0867 0 -0 0</wrench>
        </link>
        <link name='robot::right_rear_wheel'>
          <pose>-0.257372 0.984967 0.15 3.08741 1.57079 2.90894</pose>
          <velocity>-0.000483 -0.000101 -0.005207 0.012157 -0.002193 -0.00206</velocity>
          <acceleration>-0.593194 -0.709715 -10.4137 2.32327 1.24468 1.36781</acceleration>
          <wrench>-0.593194 -0.709715 -10.4137 0 -0 0</wrench>
        </link>
      </model>
      <light name='user_directional_light_0'>
        <pose>5.98576 1.89907 1 0 -0 0</pose>
      </light>
      <light name='user_directional_light_1'>
        <pose>0.092436 1.84075 1 0 -0 0</pose>
      </light>
      <light name='user_point_light_0'>
        <pose>0.500876 0.028798 1 0 -0 0</pose>
      </light>
    </state>
    <gui fullscreen='0'>
      <camera name='user_camera'>
        <pose>15.9552 0.06657 6.47243 0 0.371643 3.1322</pose>
        <view_controller>orbit</view_controller>
        <projection_type>perspective</projection_type>
      </camera>
    </gui>
  </world>
</sdf>
